2018-02-02 15:46:29,883 - teradata.udaexec - INFO - Initializing UdaExec...
2018-02-02 15:46:29,883 - teradata.udaexec - INFO - Reading config files: [u'/etc/udaexec.ini: Not Found', u'/Users/mifang/udaexec.ini: Not Found', u'/Users/mifang/Documents/Expedia/Project/tutorial/djangoTutorial/dq-djang-python-validation-webapp/myproject/myproject/myapp/resource/LibraryFile/udaexec.ini: Found']
2018-02-02 15:46:29,883 - teradata.udaexec - INFO - Found run number file: "/Users/mifang/Documents/Expedia/Project/tutorial/djangoTutorial/dq-djang-python-validation-webapp/myproject/myproject/myapp/resource/LibraryFile/.runNumber"
2018-02-02 15:46:29,883 - teradata.udaexec - INFO - Cleaning up log files older than 90 days.
2018-02-02 15:46:29,883 - teradata.udaexec - INFO - Removed 0 log files.
2018-02-02 15:46:29,945 - teradata.udaexec - INFO - Checkpoint file not found: /Users/mifang/Documents/Expedia/Project/tutorial/djangoTutorial/dq-djang-python-validation-webapp/myproject/myproject/myapp/resource/LibraryFile/ConnectTDDEV.checkpoint
2018-02-02 15:46:29,945 - teradata.udaexec - INFO - No previous checkpoint found, executing from beginning...
2018-02-02 15:46:29,946 - teradata.udaexec - INFO - Execution Details:
/********************************************************************************
 * Application Name: ConnectTDDEV
 *          Version: 2
 *       Run Number: 20180202154629-150
 *             Host: BELC02RJ96BG8WN.sea.corp.expecn.com
 *         Platform: Darwin-16.7.0-x86_64-i386-64bit
 *          OS User: mifang
 *   Python Version: 2.7.10
 *  Python Compiler: GCC 4.2.1 Compatible Apple LLVM 8.0.0 (clang-800.0.34)
 *     Python Build: ('default', 'Feb  7 2017 00:08:15')
 *  UdaExec Version: 15.10.0.21
 *     Program Name: connectTD.py
 *      Working Dir: /Users/mifang/Documents/Expedia/Project/tutorial/djangoTutorial/dq-djang-python-validation-webapp/myproject/myproject/myapp/resource/LibraryFile
 *      Git Version: git version 2.14.3 (Apple Git-98)
 *     Git Revision: 8b6bffe
 *        Git Dirty: True [?? myproject/myproject/myapp/resource/]
 *          Log Dir: /Users/mifang/Documents/Expedia/Project/tutorial/djangoTutorial/dq-djang-python-validation-webapp/myproject/myproject/myapp/resource/LibraryFile/logs
 *         Log File: /Users/mifang/Documents/Expedia/Project/tutorial/djangoTutorial/dq-djang-python-validation-webapp/myproject/myproject/myapp/resource/LibraryFile/logs/ConnectTDDEV.20180202154629-150.log
 *     Config Files: [u'/etc/udaexec.ini: Not Found', u'/Users/mifang/udaexec.ini: Not Found', u'/Users/mifang/Documents/Expedia/Project/tutorial/djangoTutorial/dq-djang-python-validation-webapp/myproject/myproject/myapp/resource/LibraryFile/udaexec.ini: Found']
 *      Query Bands: ApplicationName=ConnectTDDEV;Version=2;JobID=20180202154629-150;ClientUser=mifang;Production=False;udaAppLogFile=/Users/mifang/Documents/Expedia/Project/tutorial/djangoTutorial/dq-djang-python-validation-webapp/myproject/myproject/myapp/resource/LibraryFile/logs/ConnectTDDEV.20180202154629-150.log;gitRevision=8b6bffe;gitDirty=True;UtilityName=PyTd;UtilityVersion=15.10.0.21
********************************************************************************/
2018-02-02 15:46:29,957 - teradata.udaexec - INFO - Creating connection: {'username': 'D_DM_BEX_CLICKSTREAM_ADB', 'password': 'XXXXXX', 'method': 'odbc', 'system': 'tddev'}
2018-02-02 15:46:29,957 - teradata.tdodbc - INFO - Loading ODBC Library: libiodbc.dylib
2018-02-02 15:46:29,971 - teradata.tdodbc - INFO - Available drivers: Teradata Database ODBC Driver 16.20
2018-02-02 15:46:31,015 - teradata.udaexec - ERROR - Uncaught exception
Traceback (most recent call last):
  File "connectTD.py", line 23, in <module>
    with udaExec.connect(method=config.get('DEFAULT', 'method'), system=config.get('TDDEV', 'system'),username=config.get('TDDEV', 'username'), password=config.get('TDDEV', 'password')) as session:
  File "/Users/mifang/eb-virt/lib/python2.7/site-packages/teradata/udaexec.py", line 183, in connect
    **args))
  File "/Users/mifang/eb-virt/lib/python2.7/site-packages/teradata/tdodbc.py", line 450, in __init__
    SQL_NTS, None, 0, None, 0)
KeyboardInterrupt
2018-02-02 15:46:31,021 - teradata.udaexec - INFO - UdaExec exiting.
